<?xml version="1.0"?>

<robot name="pioneer3dx"
	xmlns:sensor="http://playerstage.sourceforge.net/gazebo/xmlschema/#sensor"
	xmlns:controller="http://playerstage.sourceforge.net/gazebo/xmlschema/#controller"
	xmlns:interface="http://playerstage.sourceforge.net/gazebo/xmlschema/#interface"
	xmlns:xacro="http://ros.org/wiki/xacro">

  <!--<include filename="$(find amr_robots_description)/urdf/materials.xacro"/>-->
  <xacro:include filename="$(find amr_robots_description)/urdf/pioneer3dx_wheel.xacro"/>

  <link name="robot_base"/>
  <joint name="robot_base_to_base_link" type="fixed">
    <origin xyz="0 0 0" rpy="0 0 0"/>
    <parent link="robot_base"/>
    <child link="base_link"/>
  </joint>

<!-- Chassis -->
	<link name="base_link">
		<inertial>
			<mass value="3.5"/>
			<!--<origin xyz="-0.025 0 -0.223"/>-->
			<origin xyz="0 0 0"/>
			<inertia ixx="1" ixy="0" ixz="0"
				 iyy="1" iyz="0"
				 izz="1"/>
		</inertial>
		<visual>
			<origin xyz="-0.045 0 0.148" rpy="0 0 0"/>
			<geometry name="pioneer_geom">
				<mesh filename="package://amr_robots_description/meshes/p3dx_meshes/chassis.stl"/>
			</geometry>
			<material name="ChassisRed">
				<color rgba="0.851 0.0 0.0 1.0"/>
			</material>
		</visual>
		<collision>
			<origin xyz="0 0 0" rpy="0 0 0"/>
				<geometry>
					<box size="0.01 0.01 0.01"/>
				</geometry>
		</collision>
	</link>

	<link name="top_plate">
		<inertial>
			<mass value="0.01"/>	
			<origin xyz="0 0 0"/>
			<inertia ixx="1" ixy="0" ixz="0"
				 iyy="1" iyz="0"
 				izz="1"/>
		</inertial>
		<visual>
			<origin xyz="0 0 0" rpy="0 0 0"/>
			<geometry name="pioneer_geom">
				<mesh filename="package://amr_robots_description/meshes/p3dx_meshes/top.stl"/>
			</geometry>
			<material name="TopBlack">
					<color rgba="0.038 0.038 0.038 1.0"/>
			</material>
		</visual>
	</link>
	<gazebo reference="top_plate">
		<!-- material value="Gazebo/Black"/ -->
		<material>Gazebo/Black</material>
	</gazebo>

    <joint name="base_top_joint" type="fixed">
		<origin xyz="-0.045 0 0.234" rpy="0 0 0"/>
		<axis xzy="0 0 1"/>
		<parent link="base_link"/>
		<child link="top_plate"/>
	</joint>

	<link name="front_sonar">
		<inertial>
			<mass value="0.0001"/>	
			<origin xyz="0 0 0"/>
			<inertia ixx="1" ixy="0" ixz="0"
				 iyy="1" iyz="0" izz="1"/>
		</inertial>
		<visual>
			<origin xyz="0 0 0" rpy="0 0 0"/>
			<geometry name="pioneer_geom">
				<mesh filename="package://amr_robots_description/meshes/p3dx_meshes/front_sonar.stl"/>
			</geometry>
			<material name="SonarYellow">
				<color rgba="0.715 0.583 0.210 1.0"/>
			</material>
		</visual>
	</link>

	<gazebo reference="front_sonar">
		<material value="Gazebo/Yellow"/>
	</gazebo>

	<joint name="base_front_joint" type="fixed">
		<origin xyz="-0.198 0 0.208" rpy="0 0 0"/>
		<parent link="base_link"/>
		<child link="front_sonar"/>
	</joint>

	<joint name="base_back_joint" type="fixed">
		<origin xyz="0.109 0 0.209" rpy="0 0 0"/>
		<parent link="base_link"/>
		<child link="back_sonar"/>
	</joint>
	<link name="back_sonar">
		<inertial>
			<mass value="0"/>	
			<origin xyz="0 0 0"/>
			<inertia ixx="1" ixy="0" ixz="0"
				 iyy="1" iyz="0" izz="1"/>
		</inertial>
		<visual>
			<origin xyz="0 0 0" rpy="0 0 0"/>
			<geometry name="pioneer_geom">
				<mesh filename="package://amr_robots_description/meshes/p3dx_meshes/back_sonar.stl"/>
			</geometry>
			<material name="SonarYellow">
				<color rgba="0.715 0.583 0.210 1.0"/>
			</material>
		</visual>
	</link>

	<!-- Caster -->
	<joint name="base_caster_swivel_joint" type="continuous">
		<origin xyz="-0.185 0 0.055" rpy="0 0 0"/>
		<anchor xyz="0 0 0"/>
    	<limit effort="100" velocity="100" k_velocity="0" />
    	<joint_properties damping="0.0" friction="0.0" />
		<parent link="base_link"/>
		<child link="caster_swivel"/>
	</joint>

	<link name="caster_swivel">
		<inertial>
			<mass value="0.1"/>	
			<origin xyz="0 0 0"/>
			<inertia ixx="0.01" ixy="0" ixz="0"
				 iyy="0.01" iyz="0" izz="0.01"/>
  	 	</inertial>
	<visual>
		<origin xyz="0 0 0" rpy="0 0 0"/>

		<geometry name="pioneer_geom">
			<mesh filename="package://amr_robots_description/meshes/p3dx_meshes/caster_swivel.stl"/>
		</geometry>
		<material name="caster_swivel">
			<color rgba="0.5 0.5 0.5 1"/>
		</material>
	</visual>
	</link>
	<gazebo reference="caster_swivel">
		<material value="Gazebo/Grey"/>
	</gazebo>

<!-- Center Wheel + Hubcap -->
	<link name="caster_hubcap">
		<inertial>
			<mass value="0.01"/>	
			<origin xyz="0 0 0"/>
			<inertia ixx="0.012411765597" ixy="-0.000711733678" ixz="0.00050272983"
				 iyy="0.015218160428" iyz="-0.000004273467" izz="0.011763977943"/>
  	 	</inertial>
	<visual>
		<origin xyz="0 0 0" rpy="0 0 0"/>
		<geometry name="pioneer_geom">
			<mesh filename="package://amr_robots_description/meshes/p3dx_meshes/caster_hubcap.stl"/>
		</geometry>
		<material name="caster_swivel">
			<color rgba="0.5 0.5 0.5 1"/>
		</material>
	</visual>
	<collision>
		<origin xyz="0 0 0" rpy="0 0 0"/>
		<geometry>
			<box size="0.05 0.05 0.05"/>
		</geometry>
	</collision>
	</link>
	<gazebo reference="caster_hubcap">
		<material value="Gazebo/Grey"/>
	</gazebo>

	<joint name="caster_swivel_hubcap_joint" type="continuous">
		<origin xyz="-0.026 0 -0.016" rpy="0 0 0"/>
		<axis xyz="0 1 0"/>
		<anchor xyz="0 0 0"/>
		<limit effort="100" velocity="100" k_velocity="0" />
		<joint_properties damping="0.0" friction="0.0" />
	  	<parent link="caster_swivel"/>
		<child link="caster_wheel"/>
	</joint>

	<link name="caster_wheel">
		<inertial>
			<mass value="0.1"/>	
			<origin xyz="0 0 0"/>
			<inertia ixx="0.012411765597" ixy="-0.000711733678" ixz="0.00050272983"
				 iyy="0.015218160428" iyz="-0.000004273467" izz="0.011763977943"/>
  	 	</inertial>
	<visual>
		<origin xyz="0 0 0" rpy="0 0 0"/>
		<geometry name="pioneer_geom">
			<mesh filename="package://amr_robots_description/meshes/p3dx_meshes/caster_wheel.stl"/>
		</geometry>
		<material name="WheelBlack">
			<color rgba="0.117 0.117 0.117 1"/>
		</material>
	</visual>
	<collision>
		<origin xyz="0 0 0" rpy="${-3.1415927/2.0} 0 0"/>
		<geometry>
			<!--<mesh filename="package://amr_robots_description/meshes/p3dx_meshes/caster_wheel.stl"/>-->
			<cylinder radius="0.0375" length="0.01"/>
		</geometry>
	</collision>
	</link>
	<gazebo reference="left_hub">
		<material value="Gazebo/Yellow"/>
	</gazebo>

	<joint name="caster_wheel_joint" type="fixed">
		<origin xyz="-0.0035 0 -0.001" rpy="0 0 0"/>
		<parent link="caster_wheel"/>
		<child link="caster_hubcap"/>
	</joint>

	<!-- Wheels -->
	<xacro:macro name="wheel" params="prefix y_offset">

		<link name="${prefix}_hub">
			<visual>
				<origin xyz="0 0 0" rpy="0 0 0"/>
				<geometry>
					<mesh filename="package://amr_robots_description/meshes/p3dx_meshes/${prefix}_hubcap.stl"/>
				</geometry>
				<material name="HubcapYellow">
					<color rgba="1.0 0.811 0.151 1.0"/>
				</material>
			</visual>
			<collision>
			<origin xyz="0 0 0" rpy="${-3.1415927/2.0} 0 0"/>
			<geometry>
				<!--<mesh filename="package://amr_robots_description/meshes/p3dx_meshes/${prefix}_wheel.stl"/>-->
				<cylinder radius="0.09" length="0.01"/>
			</geometry>
		</collision>
		</link>
		<gazebo reference="${prefix}_hub">
			<material value="Gazebo/Yellow"/>
		</gazebo>


		<joint name="${prefix}_hub_joint" type="fixed">
			<origin xyz="0 ${y_offset} 0.08" rpy="0 0 0"/>
			<parent link="base_link"/>
			<child link="${prefix}_hub"/>
			<axis xyz="0 1 0"/>
		</joint>

		<link name="${prefix}_wheel">
			<visual>
				<origin xyz="0 0 0" rpy="0 0 0"/>
				<geometry>
					<mesh filename="package://amr_robots_description/meshes/p3dx_meshes/${prefix}_wheel.stl"/>
					<!--
					<cylinder>
						<radius>0.12</radius>
						<length>0.04</length>
					</cylinder>
					-->
				</geometry>
				<material name="WheelBlack">
					<color rgba="0.117 0.117 0.117 1"/>
				</material>
			</visual>
		</link>
		<gazebo reference="${prefix}_wheel">
			<material value="Gazebo/Black"/>
		</gazebo>

		<joint name="${prefix}_wheel_joint" type="continuous">
			<origin xyz="0 0 0" rpy="0 0 0"/>

			<axis>
			<xyz>0 1 0</xyz>
			<anchor xyz="0 0 0"/>
			<!--
			<limit>
				<lower>-inf</lower>
				<upper>inf</upper>
			</limit>
			-->
			</axis>
			<limit effort="100" velocity="100" k_velocity="0" />
			<joint_properties damping="0.0" friction="0.0" />

			<parent link="${prefix}_hub"/>
			<child link="${prefix}_wheel"/>
		</joint>
		<gazebo reference="${prefix}_wheel_joint">
			<material value="Gazebo/Black"/>
		</gazebo>
	</xacro:macro>

	<xacro:wheel prefix="left" y_offset="0.17" />
	<xacro:wheel prefix="right" y_offset="-0.17" />

	<create>
		<back_sonar parent="base_link"/>
		<top_plate  parent="base_link"/>
  	</create>

	<!-- ============================= -->
	<!-- Ignition Gazebo Diff Drive Plugin -->
	<!-- ============================= -->
	<gazebo>
		<plugin
			filename="gz-sim-diff-drive-system"
			name="gz::sim::systems::DiffDrive">
			<left_joint>pioneer3dx::left_wheel_joint</left_joint>
			<right_joint>pioneer3dx::right_wheel_joint</right_joint>
			<wheel_separation>0.158</wheel_separation>
			<wheel_radius>0.12</wheel_radius>
			<!--
			<wheel_separation>0.3</wheel_separation>
			<wheel_radius>0.09</wheel_radius>
			-->
			<!--
			<topic>/model/pioneer3dx/cmd_vel</topic>
			-->
			<!--
			<enable_odom>true</enable_odom>
			<odom_frame>odom</odom_frame>
			-->
			<base_frame>base_link</base_frame>
			<publish_rate>50</publish_rate>
			<publish_joint_states>true</publish_joint_states>
		</plugin>

		<plugin
			name="gz::sim::systems::JointStatePublisher"
			filename="libgz-sim-joint-state-publisher-system.so">
		</plugin>

	</gazebo>


</robot>
