<sdf version='1.11'>
  <model name='pioneer3dx'>
	<link name='base_link'/>
    <link name='chassis'>
      <pose>-0.044999999999999998 0 0.14799999999999999 0 0 0</pose>
      <inertial>
        <mass>3.5</mass>
        <inertia>
          <ixx>1</ixx>
          <iyy>1</iyy>
          <izz>1</izz>
          <ixy>0</ixy>
          <ixz>0</ixz>
          <iyz>0</iyz>
        </inertia>
      </inertial>
      <visual name='chassis_visual'>
        <geometry>
          <mesh>
            <uri>package://amr_robots_description/meshes/p3dx_meshes/chassis.stl</uri>
          </mesh>
        </geometry>
        <material>
          <ambient>0.851000011 0 0 1</ambient>
          <diffuse>0.851000011 0 0 1</diffuse>
        </material>
      </visual>
      <collision name='chassis_collision'>
        <geometry>
          <box>
            <size>0.44500000000000001 0.27700000000000002 0.17000000000000001</size>
          </box>
        </geometry>
      </collision>
    </link>
    <joint name='chassis_joint' type='fixed'>
      <parent>base_link</parent>
      <child>chassis</child>
      <pose>0 0 0 0 0 0</pose>
    </joint>
    <link name='top_plate'>
      <pose>-0.044999999999999998 0 0.23400000000000001 0 0 0</pose>
      <inertial>
        <mass>0.01</mass>
        <inertia>
          <ixx>1</ixx>
          <iyy>1</iyy>
          <izz>1</izz>
          <ixy>0</ixy>
          <ixz>0</ixz>
          <iyz>0</iyz>
        </inertia>
      </inertial>
      <visual name='top_plate_visual'>
        <geometry>
          <mesh>
            <uri>package://amr_robots_description/meshes/p3dx_meshes/top.stl</uri>
          </mesh>
        </geometry>
        <material>
          <ambient>0.0379999988 0.0379999988 0.0379999988 1</ambient>
          <diffuse>0.0379999988 0.0379999988 0.0379999988 1</diffuse>
        </material>
      </visual>
    </link>
    <joint name='base_top_joint' type='fixed'>
      <parent>chassis</parent>
      <child>top_plate</child>
      <pose>0 0 0 0 0 0</pose>
    </joint>
    <link name='front_sonar'>
      <pose>-0.19800000000000001 0 0.20799999999999999 0 0 0</pose>
      <inertial>
        <mass>0.0001</mass>
        <inertia>
          <ixx>1</ixx>
          <iyy>1</iyy>
          <izz>1</izz>
          <ixy>0</ixy>
          <ixz>0</ixz>
          <iyz>0</iyz>
        </inertia>
      </inertial>
      <visual name='front_sonar_visual'>
        <geometry>
          <mesh>
            <uri>package://amr_robots_description/meshes/p3dx_meshes/front_sonar.stl</uri>
          </mesh>
        </geometry>
      </visual>
    </link>
    <joint name='base_front_joint' type='fixed'>
      <parent>chassis</parent>
      <child>front_sonar</child>
      <pose>0 0 0 0 0 0</pose>
    </joint>
    <link name='back_sonar'>
      <pose>0.109 0 0.20899999999999999 0 0 0</pose>
      <inertial>
        <mass>0.0001</mass>
        <inertia>
          <ixx>1</ixx>
          <iyy>1</iyy>
          <izz>1</izz>
          <ixy>0</ixy>
          <ixz>0</ixz>
          <iyz>0</iyz>
        </inertia>
      </inertial>
      <visual name='back_sonar_visual'>
        <geometry>
          <mesh>
            <uri>package://amr_robots_description/meshes/p3dx_meshes/back_sonar.stl</uri>
          </mesh>
        </geometry>
      </visual>
    </link>
    <joint name='base_back_joint' type='fixed'>
      <parent>chassis</parent>
      <child>back_sonar</child>
      <pose>0 0 0 0 0 0</pose>
    </joint>
    <link name='caster_swivel'>
      <pose>-0.185 0 0.055 0 0 0</pose>
      <inertial>
        <mass>0.10000000000000001</mass>
        <inertia>
          <ixx>0.01</ixx>
          <iyy>0.01</iyy>
          <izz>0.01</izz>
          <ixy>0</ixy>
          <ixz>0</ixz>
          <iyz>0</iyz>
        </inertia>
      </inertial>
      <visual name='caster_swivel_visual'>
        <geometry>
          <mesh>
            <uri>package://amr_robots_description/meshes/p3dx_meshes/caster_swivel.stl</uri>
          </mesh>
        </geometry>
      </visual>
    </link>
    <joint name='base_caster_swivel_joint' type='revolute'>
      <parent>base_link</parent>
      <child>caster_swivel</child>
      <axis>
        <xyz>0 0 1</xyz>
        <limit>
          <lower>-inf</lower>
          <upper>inf</upper>
        </limit>
      </axis>
    </joint>
    <link name='caster_wheel'>
      <pose>-0.21099999999999999 0 0.039 -1.5707963267948963 1.5707963267948966 0</pose>
      <inertial>
        <mass>0.10000000000000001</mass>
        <inertia>
          <ixx>0.0124</ixx>
          <iyy>0.0152</iyy>
          <izz>0.0117</izz>
          <ixy>0</ixy>
          <ixz>0</ixz>
          <iyz>0</iyz>
        </inertia>
      </inertial>
      <visual name='caster_wheel_visual'>
        <geometry>
          <cylinder>
            <radius>0.037499999999999999</radius>
            <length>0.01</length>
          </cylinder>
        </geometry>
      </visual>
      <collision name='collision'>
        <geometry>
          <cylinder>
            <radius>0.037499999999999999</radius>
            <length>0.01</length>
          </cylinder>
        </geometry>
        <surface>
          <friction>
            <ode>
              <mu>100000</mu>
              <mu2>100000</mu2>
              <slip1>0</slip1>
              <slip2>0</slip2>
            </ode>
          </friction>
        </surface>
      </collision>
      <inertial>
        <pose>0 0 0 1.5707963267948963 0 0</pose>
        <mass>0.20000000000000001</mass>
        <inertia>
          <ixx>7.1979166666666657e-05</ixx>
          <ixy>0</ixy>
          <ixz>0</ixz>
          <iyy>7.1979166666666657e-05</iyy>
          <iyz>0</iyz>
          <izz>0.00014062499999999999</izz>
        </inertia>
      </inertial>
    </link>
    <joint name='caster_swivel_hubcap_joint' type='revolute'>
      <parent>caster_swivel</parent>
      <child>caster_wheel</child>
      <axis>
        <xyz>0 0 1</xyz>
        <limit>
          <lower>-10000000000000000</lower>
          <upper>10000000000000000</upper>
          <effort>10</effort>
          <velocity>10</velocity>
        </limit>
      </axis>
    </joint>
    <link name='left_hub'>
      <pose>0 0.17000000000000001 0.12 0 0 0</pose>
      <visual name='left_hub_visual'>
        <geometry>
          <mesh>
            <uri>package://amr_robots_description/meshes/p3dx_meshes/left_hubcap.stl</uri>
          </mesh>
        </geometry>
      </visual>
      <inertial>
        <pose>0 0 0 1.5707963267948963 0 0</pose>
        <mass>0.10000000000000001</mass>
        <inertia>
          <ixx>0.00013583333333333329</ixx>
          <ixy>0</ixy>
          <ixz>0</ixz>
          <iyy>0.00013583333333333329</iyy>
          <iyz>0</iyz>
          <izz>0.00024499999999999994</izz>
        </inertia>
      </inertial>
    </link>
    <joint name='left_hub_joint' type='fixed'>
      <parent>chassis</parent>
      <child>left_hub</child>
      <pose>0 0.17000000000000001 0.12 0 0 0</pose>
    </joint>
    <link name='left_wheel'>
      <pose>0 0.17000000000000001 0.12 -1.5707963267948963 1.5707963267948966 0</pose>
      <visual name='left_wheel_visual'>
        <geometry>
          <cylinder>
            <radius>0.12</radius>
            <length>0.040000000000000001</length>
          </cylinder>
        </geometry>
        <material>
          <ambient>0.0379999988 0.0379999988 0.0379999988 1</ambient>
          <diffuse>0.0379999988 0.0379999988 0.0379999988 1</diffuse>
        </material>
      </visual>
      <collision name='collision'>
        <geometry>
          <cylinder>
            <radius>0.12</radius>
            <length>0.040000000000000001</length>
          </cylinder>
        </geometry>
        <surface>
          <friction>
            <ode>
              <mu>100000</mu>
              <mu2>100000</mu2>
              <slip1>0</slip1>
              <slip2>0</slip2>
            </ode>
          </friction>
        </surface>
      </collision>
      <inertial>
        <pose>0 0 0 1.5707963267948963 0 0</pose>
        <mass>1.5</mass>
        <inertia>
          <ixx>0.0055999999999999991</ixx>
          <ixy>0</ixy>
          <ixz>0</ixz>
          <iyy>0.0055999999999999991</iyy>
          <iyz>0</iyz>
          <izz>0.010800000000000001</izz>
        </inertia>
      </inertial>
    </link>
    <joint name='left_wheel_joint' type='revolute'>
      <parent>left_hub</parent>
      <child>left_wheel</child>
      <pose>0 0 0 0 0 0</pose>
      <axis>
        <xyz>0 0 1</xyz>
        <limit>
          <lower>-10000000000000000</lower>
          <upper>10000000000000000</upper>
          <effort>10</effort>
          <velocity>10</velocity>
        </limit>
      </axis>
    </joint>
    <link name='right_hub'>
      <pose>0 -0.17000000000000001 0.12 0 0 0</pose>
      <visual name='right_hub_visual'>
        <geometry>
          <mesh>
            <uri>package://amr_robots_description/meshes/p3dx_meshes/right_hubcap.stl</uri>
          </mesh>
        </geometry>
      </visual>
      <inertial>
        <pose>0 0 0 1.5707963267948963 0 0</pose>
        <mass>0.10000000000000001</mass>
        <inertia>
          <ixx>0.00013583333333333329</ixx>
          <ixy>0</ixy>
          <ixz>0</ixz>
          <iyy>0.00013583333333333329</iyy>
          <iyz>0</iyz>
          <izz>0.00024499999999999994</izz>
        </inertia>
      </inertial>
    </link>
    <joint name='right_hub_joint' type='fixed'>
      <parent>chassis</parent>
      <child>right_hub</child>
      <pose>0 -0.17000000000000001 0.12 0 0 0</pose>
    </joint>
    <link name='right_wheel'>
      <pose>0 -0.17000000000000001 0.12 -1.5707963267948963 1.5707963267948966 0</pose>
      <visual name='right_wheel_visual'>
        <geometry>
          <cylinder>
            <radius>0.12</radius>
            <length>0.040000000000000001</length>
          </cylinder>
        </geometry>
        <material>
          <ambient>0.0379999988 0.0379999988 0.0379999988 1</ambient>
          <diffuse>0.0379999988 0.0379999988 0.0379999988 1</diffuse>
        </material>
      </visual>
      <collision name='collision'>
        <geometry>
          <cylinder>
            <radius>0.12</radius>
            <length>0.040000000000000001</length>
          </cylinder>
        </geometry>
        <surface>
          <friction>
            <ode>
              <mu>100000</mu>
              <mu2>100000</mu2>
              <slip1>0</slip1>
              <slip2>0</slip2>
            </ode>
          </friction>
        </surface>
      </collision>
      <inertial>
        <pose>0 0 0 1.5707963267948963 0 0</pose>
        <mass>1.5</mass>
        <inertia>
          <ixx>0.0055999999999999991</ixx>
          <ixy>0</ixy>
          <ixz>0</ixz>
          <iyy>0.0055999999999999991</iyy>
          <iyz>0</iyz>
          <izz>0.010800000000000001</izz>
        </inertia>
      </inertial>
    </link>
    <joint name='right_wheel_joint' type='revolute'>
      <parent>right_hub</parent>
      <child>right_wheel</child>
      <pose>0 0 0 0 0 0</pose>
      <axis>
        <xyz>0 0 1</xyz>
        <limit>
          <lower>-10000000000000000</lower>
          <upper>10000000000000000</upper>
          <effort>10</effort>
          <velocity>10</velocity>
        </limit>
      </axis>
    </joint>
    <plugin name='gz::sim::systems::DiffDrive' filename='gz-sim-diff-drive-system'>
      <left_joint>left_wheel_joint</left_joint>
      <right_joint>right_wheel_joint</right_joint>
      <wheel_separation>0.34</wheel_separation>
      <wheel_radius>0.12</wheel_radius>
    </plugin>
    <plugin name='gz::sim::systems::JointStatePublisher' filename='libgz-sim-joint-state-publisher-system.so'/>
  </model>
  <link name='base_link'/>
</sdf>
